<?xml version="1.0" encoding="UTF-8"?>
<testng-results ignored="0" total="6" passed="3" failed="3" skipped="0">
  <reporter-output>
  </reporter-output>
  <suite started-at="2024-06-04T11:09:48 IST" name="Default suite" finished-at="2024-06-04T11:10:53 IST" duration-ms="64605">
    <groups>
    </groups>
    <test started-at="2024-06-04T11:09:48 IST" name="Default test" finished-at="2024-06-04T11:10:53 IST" duration-ms="64605">
      <class name="assignment.FlexiPillsAssign">
        <test-method is-config="true" signature="setup()[pri:0, instance:assignment.FlexiPillsAssign@7bd7d6d6]" started-at="2024-06-04T11:09:48 IST" name="setup" finished-at="2024-06-04T11:10:03 IST" duration-ms="15277" status="PASS">
          <reporter-output>
          </reporter-output>
        </test-method> <!-- setup -->
        <test-method signature="login()[pri:1, instance:assignment.FlexiPillsAssign@7bd7d6d6]" started-at="2024-06-04T11:10:03 IST" name="login" finished-at="2024-06-04T11:10:26 IST" duration-ms="22538" status="PASS">
          <reporter-output>
          </reporter-output>
        </test-method> <!-- login -->
        <test-method signature="addToCart()[pri:2, instance:assignment.FlexiPillsAssign@7bd7d6d6]" started-at="2024-06-04T11:10:26 IST" name="addToCart" finished-at="2024-06-04T11:10:35 IST" duration-ms="9331" status="FAIL">
          <exception class="org.json.JSONException">
            <message>
              <![CDATA[JSONObject["success"] is not a Boolean.]]>
            </message>
            <full-stacktrace>
              <![CDATA[org.json.JSONException: JSONObject["success"] is not a Boolean.
at org.json.JSONObject.wrongValueFormatException(JSONObject.java:2628)
at org.json.JSONObject.getBoolean(JSONObject.java:623)
at assignment.FlexiPillsAssign.addToCartApi(FlexiPillsAssign.java:118)
at assignment.FlexiPillsAssign.addToCart(FlexiPillsAssign.java:96)
at java.base/jdk.internal.reflect.NativeMethodAccessorImpl.invoke0(Native Method)
at java.base/jdk.internal.reflect.NativeMethodAccessorImpl.invoke(NativeMethodAccessorImpl.java:77)
at java.base/jdk.internal.reflect.DelegatingMethodAccessorImpl.invoke(DelegatingMethodAccessorImpl.java:43)
at java.base/java.lang.reflect.Method.invoke(Method.java:568)
at org.testng.internal.invokers.MethodInvocationHelper.invokeMethod(MethodInvocationHelper.java:139)
at org.testng.internal.invokers.TestInvoker.invokeMethod(TestInvoker.java:677)
at org.testng.internal.invokers.TestInvoker.invokeTestMethod(TestInvoker.java:221)
at org.testng.internal.invokers.MethodRunner.runInSequence(MethodRunner.java:50)
at org.testng.internal.invokers.TestInvoker$MethodInvocationAgent.invoke(TestInvoker.java:969)
at org.testng.internal.invokers.TestInvoker.invokeTestMethods(TestInvoker.java:194)
at org.testng.internal.invokers.TestMethodWorker.invokeTestMethods(TestMethodWorker.java:148)
at org.testng.internal.invokers.TestMethodWorker.run(TestMethodWorker.java:128)
at java.base/java.util.ArrayList.forEach(ArrayList.java:1511)
at org.testng.TestRunner.privateRun(TestRunner.java:829)
at org.testng.TestRunner.run(TestRunner.java:602)
at org.testng.SuiteRunner.runTest(SuiteRunner.java:437)
at org.testng.SuiteRunner.runSequentially(SuiteRunner.java:431)
at org.testng.SuiteRunner.privateRun(SuiteRunner.java:391)
at org.testng.SuiteRunner.run(SuiteRunner.java:330)
at org.testng.SuiteRunnerWorker.runSuite(SuiteRunnerWorker.java:52)
at org.testng.SuiteRunnerWorker.run(SuiteRunnerWorker.java:95)
at org.testng.TestNG.runSuitesSequentially(TestNG.java:1256)
at org.testng.TestNG.runSuitesLocally(TestNG.java:1176)
at org.testng.TestNG.runSuites(TestNG.java:1099)
at org.testng.TestNG.run(TestNG.java:1067)
at org.testng.remote.AbstractRemoteTestNG.run(AbstractRemoteTestNG.java:115)
at org.testng.remote.RemoteTestNG.initAndRun(RemoteTestNG.java:293)
at org.testng.remote.RemoteTestNG.main(RemoteTestNG.java:91)
]]>
            </full-stacktrace>
          </exception> <!-- org.json.JSONException -->
          <reporter-output>
          </reporter-output>
        </test-method> <!-- addToCart -->
        <test-method signature="createOrder()[pri:3, instance:assignment.FlexiPillsAssign@7bd7d6d6]" started-at="2024-06-04T11:10:35 IST" name="createOrder" finished-at="2024-06-04T11:10:51 IST" duration-ms="15784" status="FAIL">
          <exception class="java.lang.AssertionError">
            <message>
              <![CDATA[expected [200] but found [500]]]>
            </message>
            <full-stacktrace>
              <![CDATA[java.lang.AssertionError: expected [200] but found [500]
at org.testng.Assert.fail(Assert.java:110)
at org.testng.Assert.failNotEquals(Assert.java:1577)
at org.testng.Assert.assertEqualsImpl(Assert.java:149)
at org.testng.Assert.assertEquals(Assert.java:131)
at org.testng.Assert.assertEquals(Assert.java:1418)
at org.testng.Assert.assertEquals(Assert.java:1382)
at org.testng.Assert.assertEquals(Assert.java:1428)
at assignment.FlexiPillsAssign.createOrderApi(FlexiPillsAssign.java:179)
at assignment.FlexiPillsAssign.createOrder(FlexiPillsAssign.java:150)
at java.base/jdk.internal.reflect.NativeMethodAccessorImpl.invoke0(Native Method)
at java.base/jdk.internal.reflect.NativeMethodAccessorImpl.invoke(NativeMethodAccessorImpl.java:77)
at java.base/jdk.internal.reflect.DelegatingMethodAccessorImpl.invoke(DelegatingMethodAccessorImpl.java:43)
at java.base/java.lang.reflect.Method.invoke(Method.java:568)
at org.testng.internal.invokers.MethodInvocationHelper.invokeMethod(MethodInvocationHelper.java:139)
at org.testng.internal.invokers.TestInvoker.invokeMethod(TestInvoker.java:677)
at org.testng.internal.invokers.TestInvoker.invokeTestMethod(TestInvoker.java:221)
at org.testng.internal.invokers.MethodRunner.runInSequence(MethodRunner.java:50)
at org.testng.internal.invokers.TestInvoker$MethodInvocationAgent.invoke(TestInvoker.java:969)
at org.testng.internal.invokers.TestInvoker.invokeTestMethods(TestInvoker.java:194)
at org.testng.internal.invokers.TestMethodWorker.invokeTestMethods(TestMethodWorker.java:148)
at org.testng.internal.invokers.TestMethodWorker.run(TestMethodWorker.java:128)
at java.base/java.util.ArrayList.forEach(ArrayList.java:1511)
at org.testng.TestRunner.privateRun(TestRunner.java:829)
at org.testng.TestRunner.run(TestRunner.java:602)
at org.testng.SuiteRunner.runTest(SuiteRunner.java:437)
at org.testng.SuiteRunner.runSequentially(SuiteRunner.java:431)
at org.testng.SuiteRunner.privateRun(SuiteRunner.java:391)
at org.testng.SuiteRunner.run(SuiteRunner.java:330)
at org.testng.SuiteRunnerWorker.runSuite(SuiteRunnerWorker.java:52)
at org.testng.SuiteRunnerWorker.run(SuiteRunnerWorker.java:95)
at org.testng.TestNG.runSuitesSequentially(TestNG.java:1256)
at org.testng.TestNG.runSuitesLocally(TestNG.java:1176)
at org.testng.TestNG.runSuites(TestNG.java:1099)
at org.testng.TestNG.run(TestNG.java:1067)
at org.testng.remote.AbstractRemoteTestNG.run(AbstractRemoteTestNG.java:115)
at org.testng.remote.RemoteTestNG.initAndRun(RemoteTestNG.java:293)
at org.testng.remote.RemoteTestNG.main(RemoteTestNG.java:91)
]]>
            </full-stacktrace>
          </exception> <!-- java.lang.AssertionError -->
          <reporter-output>
          </reporter-output>
        </test-method> <!-- createOrder -->
        <test-method signature="testInvalidLogin()[pri:4, instance:assignment.FlexiPillsAssign@7bd7d6d6]" started-at="2024-06-04T11:10:51 IST" name="testInvalidLogin" finished-at="2024-06-04T11:10:52 IST" duration-ms="633" status="FAIL">
          <exception class="java.lang.AssertionError">
            <message>
              <![CDATA[expected [401] but found [311]]]>
            </message>
            <full-stacktrace>
              <![CDATA[java.lang.AssertionError: expected [401] but found [311]
at org.testng.Assert.fail(Assert.java:110)
at org.testng.Assert.failNotEquals(Assert.java:1577)
at org.testng.Assert.assertEqualsImpl(Assert.java:149)
at org.testng.Assert.assertEquals(Assert.java:131)
at org.testng.Assert.assertEquals(Assert.java:1418)
at org.testng.Assert.assertEquals(Assert.java:1382)
at org.testng.Assert.assertEquals(Assert.java:1428)
at assignment.FlexiPillsAssign.testInvalidLogin(FlexiPillsAssign.java:204)
at java.base/jdk.internal.reflect.NativeMethodAccessorImpl.invoke0(Native Method)
at java.base/jdk.internal.reflect.NativeMethodAccessorImpl.invoke(NativeMethodAccessorImpl.java:77)
at java.base/jdk.internal.reflect.DelegatingMethodAccessorImpl.invoke(DelegatingMethodAccessorImpl.java:43)
at java.base/java.lang.reflect.Method.invoke(Method.java:568)
at org.testng.internal.invokers.MethodInvocationHelper.invokeMethod(MethodInvocationHelper.java:139)
at org.testng.internal.invokers.TestInvoker.invokeMethod(TestInvoker.java:677)
at org.testng.internal.invokers.TestInvoker.invokeTestMethod(TestInvoker.java:221)
at org.testng.internal.invokers.MethodRunner.runInSequence(MethodRunner.java:50)
at org.testng.internal.invokers.TestInvoker$MethodInvocationAgent.invoke(TestInvoker.java:969)
at org.testng.internal.invokers.TestInvoker.invokeTestMethods(TestInvoker.java:194)
at org.testng.internal.invokers.TestMethodWorker.invokeTestMethods(TestMethodWorker.java:148)
at org.testng.internal.invokers.TestMethodWorker.run(TestMethodWorker.java:128)
at java.base/java.util.ArrayList.forEach(ArrayList.java:1511)
at org.testng.TestRunner.privateRun(TestRunner.java:829)
at org.testng.TestRunner.run(TestRunner.java:602)
at org.testng.SuiteRunner.runTest(SuiteRunner.java:437)
at org.testng.SuiteRunner.runSequentially(SuiteRunner.java:431)
at org.testng.SuiteRunner.privateRun(SuiteRunner.java:391)
at org.testng.SuiteRunner.run(SuiteRunner.java:330)
at org.testng.SuiteRunnerWorker.runSuite(SuiteRunnerWorker.java:52)
at org.testng.SuiteRunnerWorker.run(SuiteRunnerWorker.java:95)
at org.testng.TestNG.runSuitesSequentially(TestNG.java:1256)
at org.testng.TestNG.runSuitesLocally(TestNG.java:1176)
at org.testng.TestNG.runSuites(TestNG.java:1099)
at org.testng.TestNG.run(TestNG.java:1067)
at org.testng.remote.AbstractRemoteTestNG.run(AbstractRemoteTestNG.java:115)
at org.testng.remote.RemoteTestNG.initAndRun(RemoteTestNG.java:293)
at org.testng.remote.RemoteTestNG.main(RemoteTestNG.java:91)
]]>
            </full-stacktrace>
          </exception> <!-- java.lang.AssertionError -->
          <reporter-output>
          </reporter-output>
        </test-method> <!-- testInvalidLogin -->
        <test-method signature="testInvalidAddToCart()[pri:5, instance:assignment.FlexiPillsAssign@7bd7d6d6]" started-at="2024-06-04T11:10:52 IST" name="testInvalidAddToCart" finished-at="2024-06-04T11:10:52 IST" duration-ms="424" status="PASS">
          <reporter-output>
          </reporter-output>
        </test-method> <!-- testInvalidAddToCart -->
        <test-method signature="testInvalidCreateOrder()[pri:6, instance:assignment.FlexiPillsAssign@7bd7d6d6]" started-at="2024-06-04T11:10:52 IST" name="testInvalidCreateOrder" finished-at="2024-06-04T11:10:53 IST" duration-ms="513" status="PASS">
          <reporter-output>
          </reporter-output>
        </test-method> <!-- testInvalidCreateOrder -->
      </class> <!-- assignment.FlexiPillsAssign -->
    </test> <!-- Default test -->
  </suite> <!-- Default suite -->
</testng-results>
